Workbook

Sheet monthly_category_revenue
A1: category | B1: month | C1: total_order | D1: total_revenue | E1: avg_revenue
A2: Bakery | B2: 46023 | C2: 6 | D2: 735 | E2: 122.5
A3: Bakery | B3: 46054 | C3: 8 | D3: 2440 | E3: 305
A4: Bakery | B4: 46082 | C4: 11 | D4: 3090 | E4: 280.90909
A5: Bakery | B5: 46113 | C5: 13 | D5: 3115 | E5: 239.61538
A6: Bakery | B6: 46143 | C6: 15 | D6: 3695 | E6: 246.33333
A7: Bakery | B7: 46174 | C7: 14 | D7: 2335 | E7: 166.78571
A8: Dairy & Eggs | B8: 46023 | C8: 9 | D8: 2035 | E8: 226.11111
A9: Dairy & Eggs | B9: 46054 | C9: 8 | D9: 1935 | E9: 241.875
A10: Dairy & Eggs | B10: 46082 | C10: 15 | D10: 3163 | E10: 210.86667
A11: Dairy & Eggs | B11: 46113 | C11: 9 | D11: 1650 | E11: 183.33333
A12: Dairy & Eggs | B12: 46143 | C12: 14 | D12: 3479 | E12: 248.5
A13: Dairy & Eggs | B13: 46174 | C13: 11 | D13: 1828 | E13: 166.18182
... A37: Snacks & Beverages | B37: 46174 | C37: 15 | D37: 1960 | E37: 130.66667

Sheet Pivot Table 2
A1: category | B1: total_revenue
A2: Bakery | B2: 735
B3: 2335
B4: 2440
B5: 3090
B6: 3115
B7: 3695
A8: Bakery Total
A9: Dairy & Eggs | B9: 1650
B10: 1828
B11: 1935
B12: 2035
B13: 3163
B14: 3479
A15: Dairy & Eggs Total
A16: Fruits & Vegetables | B16: 1060
B17: 1290
B18: 1400
B19: 1870
B20: 2080
B21: 2090
A22: Fruits & Vegetables Total
A23: Household Essentials | B23: 1885
B24: 2099
B25: 3477
B26: 3650
B27: 5113
B28: 5491
A29: Household Essentials Total
A30: Personal Care | B30: 1970
B31: 2177
B32: 2775
B33: 2807
B34: 3045
B35: 3608
A36: Personal Care Total
A37: Snacks & Beverages | B37: 1290
B38: 1330
B39: 1665
B40: 1670
...

Sheet Detail1
A1: category | B1: month | C1: total_order | D1: total_revenue | E1: avg_revenue

Sheet Pivot Table 1
A1: category | B1: total_revenue
A2: Bakery | B2: 735
B3: 2335
B4: 2440
B5: 3090
B6: 3115
B7: 3695
A8: Bakery Total
A9: Dairy & Eggs | B9: 1650
B10: 1828
B11: 1935
B12: 2035
B13: 3163
B14: 3479
A15: Dairy & Eggs Total
A16: Fruits & Vegetables | B16: 1060
B17: 1290
B18: 1400
B19: 1870
B20: 2080
B21: 2090
A22: Fruits & Vegetables Total
A23: Household Essentials | B23: 1885
B24: 2099
B25: 3477
B26: 3650
B27: 5113
B28: 5491
A29: Household Essentials Total
A30: Personal Care | B30: 1970
B31: 2177
B32: 2775
B33: 2807
B34: 3045
B35: 3608
A36: Personal Care Total
A37: Snacks & Beverages | B37: 1290
B38: 1330
B39: 1665
B40: 1670
...

Sheet Sheet1
A1: category | B1: target\_revenue\_inr" | C1: actual\_revenue
A2: Fruits & Vegetables | B2: 12000 | C2: =SUMIF(monthly_category_revenue!A:A, A2, monthly_category_revenue!D:D) -> 9790
A3: Dairy & Eggs | B3: 16500 | C3: =SUMIF(monthly_category_revenue!A:A, A3, monthly_category_revenue!D:D) -> 14090
A4: Snacks & Beverages | B4: 13000 | C4: =SUMIF(monthly_category_revenue!A:A, A4, monthly_category_revenue!D:D) -> 10895
A5: Personal Care | B5: 15500 | C5: =SUMIF(monthly_category_revenue!A:A, A5, monthly_category_revenue!D:D) -> 16382
A6: Household Essentials | B6: 17000 | C6: =SUMIF(monthly_category_revenue!A:A, A6, monthly_category_revenue!D:D) -> 21715
A7: Bakery | B7: 12000 | C7: =SUMIF(monthly_category_revenue!A:A, A7, monthly_category_revenue!D:D) -> 15410

Sheet Sheet2
A1: category | B1: target\_revenue\_inr" | C1: actual\_revenue | D1: Variance | E1: Percentage Variance | F1: Nested IF | G1: Match Part 1
A2: Fruits & Vegetables | B2: 12000 | C2: =SUMIF(monthly_category_revenue!A:A, A2, monthly_category_revenue!D:D) -> 9790 | D2: =C2-B2 -> -2210 | E2: =((C2-B2)/B2) -> -0.18416667 | F2: =IF(B2>=C2,"Above Target",IF((C2-B2)/C2<=15%,"Below Target - Watch","Below Target - Critical")) -> Above Target | G2: Yes
A3: Dairy & Eggs | B3: 16500 | C3: =SUMIF(monthly_category_revenue!A:A, A3, monthly_category_revenue!D:D) -> 14090 | D3: =C3-B3 -> -2410 | E3: =((C3-B3)/B3) -> -0.14606061 | F3: =IF(B3>=C3,"Above Target",IF((C3-B3)/C3<=15%,"Below Target - Watch","Below Target - Critical")) -> Above Target | G3: Yes
A4: Snacks & Beverages | B4: 13000 | C4: =SUMIF(monthly_category_revenue!A:A, A4, monthly_category_revenue!D:D) -> 10895 | D4: =C4-B4 -> -2105 | E4: =((C4-B4)/B4) -> -0.16192308 | F4: =IF(B4>=C4,"Above Target",IF((C4-B4)/C4<=15%,"Below Target - Watch","Below Target - Critical")) -> Above Target | G4: Yes
A5: Personal Care | B5: 15500 | C5: =SUMIF(monthly_category_revenue!A:A, A5, monthly_category_revenue!D:D) -> 16382 | D5: =C5-B5 -> 882 | E5: =((C5-B5)/B5) -> 0.056903226 | F5: =IF(B5>=C5,"Above Target",IF((C5-B5)/C5<=15%,"Below Target - Watch","Below Target - Critical")) -> Below Target - Watch | G5: Yes
A6: Household Essentials | B6: 17000 | C6: =SUMIF(monthly_category_revenue!A:A, A6, monthly_category_revenue!D:D) -> 21715 | D6: =C6-B6 -> 4715 | E6: =((C6-B6)/B6) -> 0.27735294 | F6: =IF(B6>=C6,"Above Target",IF((C6-B6)/C6<=15%,"Below Target - Watch","Below Target - Critical")) -> Below Target - Critical | G6: Yes
A7: Bakery | B7: 12000 | C7: =SUMIF(monthly_category_revenue!A:A, A7, monthly_category_revenue!D:D) -> 15410 | D7: =C7-B7 -> 3410 | E7: =((C7-B7)/B7) -> 0.28416667 | F7: =IF(B7>=C7,"Above Target",IF((C7-B7)/C7<=15%,"Below Target - Watch","Below Target - Critical")) -> Below Target - Critical | G7: Yes
